<?xml version="1.0" ?>
<!-- This file was generated by robot assembler -->
<robot name="tmp2_robot"
       xmlns:xi="http://www.w3.org/2001/XInclude"
       xmlns:gazebo="http://playerstage.sourceforge.net/gazebo/xmlschema/#gz"
       xmlns:model="http://playerstage.sourceforge.net/gazebo/xmlschema/#model"
       xmlns:sensor="http://playerstage.sourceforge.net/gazebo/xmlschema/#sensor"
       xmlns:body="http://playerstage.sourceforge.net/gazebo/xmlschema/#body"
       xmlns:geom="http://playerstage.sourceforge.net/gazebo/xmlschema/#geom"
       xmlns:joint="http://playerstage.sourceforge.net/gazebo/xmlschema/#joint"
       xmlns:interface="http://playerstage.sourceforge.net/gazebo/xmlschema/#interface"
       xmlns:rendering="http://playerstage.sourceforge.net/gazebo/xmlschema/#rendering"
       xmlns:renderable="http://playerstage.sourceforge.net/gazebo/xmlschema/#renderable"
       xmlns:controller="http://playerstage.sourceforge.net/gazebo/xmlschema/#controller"
       xmlns:physics="http://playerstage.sourceforge.net/gazebo/xmlschema/#physics"
       xmlns:xacro="http://www.ros.org/wiki/xacro">
  <xacro:macro name="gazebo_link_reference" params="link_name mu1:=0.9 mu2:=0.9" >
    <gazebo reference="${link_name}">
      <mu1>${mu1}</mu1>
      <mu2>${mu2}</mu2>
    </gazebo>
  </xacro:macro>
  <xacro:macro name="gazebo_transmission" params="joint_name" >
    <transmission name="${joint_name}_trans">
      <type>transmission_interface/SimpleTransmission</type>
      <joint name="${joint_name}">
        <hardwareInterface>hardware_interface/VelocityJointInterface</hardwareInterface>
        <!--hardwareInterface>hardware_interface/EffortJointInterface</hardwareInterface-->
      </joint>
      <actuator name="${joint_name}_motor">
        <hardwareInterface>hardware_interface/VelocityJointInterface</hardwareInterface>
        <!--hardwareInterface>hardware_interface/EffortJointInterface</hardwareInterface-->
        <mechanicalReduction>1</mechanicalReduction>
      </actuator>
    </transmission>
  </xacro:macro>
  <xacro:macro name="no_gazebo_transmission" params="joint_name" >
  </xacro:macro>
  <xacro:gazebo_link_reference link_name="BASE" />
  <link name="BASE">
  <inertial>
     <mass value="0.748"/>
     <origin rpy="0 0 0" xyz="-0.00162 1.763058e-17 0.020468"/>
     <inertia ixx="0.001757" ixy="-2.382876e-19" ixz="5.475789e-05" iyy="0.001148" iyz="-1.455192e-19" izz="0.000876"/>
  </inertial>
  <visual>
     <origin xyz="0.000000 0.000000 0.000000" rpy="0.00000000 -0.00000000 0.00000000"/>
     <geometry>
     <mesh filename="package://robot_assembler/meshes/body-parts-a.dae" scale="1.000000 1.000000 1.000000"/>
     </geometry>
  </visual>
  <collision>
     <origin xyz="0.000000 0.000000 0.000000" rpy="0.00000000 -0.00000000 0.00000000"/>
     <geometry>
     <mesh filename="package://robot_assembler/meshes/body-parts-a.dae" scale="1.000000 1.000000 1.000000"/>
     </geometry>
  </collision>
  <visual>
     <origin xyz="0.012000 -0.030000 0.025000" rpy="0.78539816 1.57079633 -0.78539816"/>
     <geometry>
     <mesh filename="package://robot_assembler/meshes/xm430_dynamixel.dae" scale="1.000000 1.000000 1.000000"/>
     </geometry>
  </visual>
  <collision>
     <origin xyz="0.012000 -0.030000 0.025000" rpy="0.78539816 1.57079633 -0.78539816"/>
     <geometry>
     <mesh filename="package://robot_assembler/meshes/xm430_dynamixel.dae" scale="1.000000 1.000000 1.000000"/>
     </geometry>
  </collision>
  <visual>
     <origin xyz="-0.004000 -0.030000 0.058750" rpy="-3.14159265 -0.00000000 -3.14159265"/>
     <geometry>
     <mesh filename="package://robot_assembler/meshes/fr12_s102.dae" scale="1.000000 1.000000 1.000000"/>
     </geometry>
  </visual>
  <collision>
     <origin xyz="-0.004000 -0.030000 0.058750" rpy="-3.14159265 -0.00000000 -3.14159265"/>
     <geometry>
     <mesh filename="package://robot_assembler/meshes/fr12_s102.dae" scale="1.000000 1.000000 1.000000"/>
     </geometry>
  </collision>
  <visual>
     <origin xyz="-0.004000 -0.030000 0.079750" rpy="1.57079633 -0.00000000 -1.57079633"/>
     <geometry>
     <mesh filename="package://robot_assembler/meshes/xm430_dynamixel.dae" scale="1.000000 1.000000 1.000000"/>
     </geometry>
  </visual>
  <collision>
     <origin xyz="-0.004000 -0.030000 0.079750" rpy="1.57079633 -0.00000000 -1.57079633"/>
     <geometry>
     <mesh filename="package://robot_assembler/meshes/xm430_dynamixel.dae" scale="1.000000 1.000000 1.000000"/>
     </geometry>
  </collision>
  <visual>
     <origin xyz="0.012000 0.030000 0.025000" rpy="-0.78539816 -1.57079633 -0.78539816"/>
     <geometry>
     <mesh filename="package://robot_assembler/meshes/xm430_dynamixel.dae" scale="1.000000 1.000000 1.000000"/>
     </geometry>
  </visual>
  <collision>
     <origin xyz="0.012000 0.030000 0.025000" rpy="-0.78539816 -1.57079633 -0.78539816"/>
     <geometry>
     <mesh filename="package://robot_assembler/meshes/xm430_dynamixel.dae" scale="1.000000 1.000000 1.000000"/>
     </geometry>
  </collision>
  <visual>
     <origin xyz="-0.004000 0.030000 0.058750" rpy="-3.14159265 -0.00000000 -3.14159265"/>
     <geometry>
     <mesh filename="package://robot_assembler/meshes/fr12_s102.dae" scale="1.000000 1.000000 1.000000"/>
     </geometry>
  </visual>
  <collision>
     <origin xyz="-0.004000 0.030000 0.058750" rpy="-3.14159265 -0.00000000 -3.14159265"/>
     <geometry>
     <mesh filename="package://robot_assembler/meshes/fr12_s102.dae" scale="1.000000 1.000000 1.000000"/>
     </geometry>
  </collision>
  <visual>
     <origin xyz="-0.004000 0.030000 0.079750" rpy="1.57079633 -0.00000000 -1.57079633"/>
     <geometry>
     <mesh filename="package://robot_assembler/meshes/xm430_dynamixel.dae" scale="1.000000 1.000000 1.000000"/>
     </geometry>
  </visual>
  <collision>
     <origin xyz="-0.004000 0.030000 0.079750" rpy="1.57079633 -0.00000000 -1.57079633"/>
     <geometry>
     <mesh filename="package://robot_assembler/meshes/xm430_dynamixel.dae" scale="1.000000 1.000000 1.000000"/>
     </geometry>
  </collision>
  <visual>
     <origin xyz="0.012000 -0.032000 -0.021000" rpy="3.14159265 0.00000000 1.57079633"/>
     <geometry>
     <mesh filename="package://robot_assembler/meshes/xm430_dynamixel.dae" scale="1.000000 1.000000 1.000000"/>
     </geometry>
  </visual>
  <collision>
     <origin xyz="0.012000 -0.032000 -0.021000" rpy="3.14159265 0.00000000 1.57079633"/>
     <geometry>
     <mesh filename="package://robot_assembler/meshes/xm430_dynamixel.dae" scale="1.000000 1.000000 1.000000"/>
     </geometry>
  </collision>
  <visual>
     <origin xyz="0.012000 0.032000 -0.021000" rpy="3.14159265 0.00000000 1.57079633"/>
     <geometry>
     <mesh filename="package://robot_assembler/meshes/xm430_dynamixel.dae" scale="1.000000 1.000000 1.000000"/>
     </geometry>
  </visual>
  <collision>
     <origin xyz="0.012000 0.032000 -0.021000" rpy="3.14159265 0.00000000 1.57079633"/>
     <geometry>
     <mesh filename="package://robot_assembler/meshes/xm430_dynamixel.dae" scale="1.000000 1.000000 1.000000"/>
     </geometry>
  </collision>
  </link>
  <xacro:gazebo_link_reference link_name="LINK0" />
  <link name="LINK0">
  <inertial>
     <mass value="0.016"/>
     <origin rpy="0 0 0" xyz="0.01 -0.004807 0.0148"/>
     <inertia ixx="3.031831e-06" ixy="1.651328e-22" ixz="1.480093e-21" iyy="3.409547e-06" iyz="3.860268e-22" izz="4.104951e-06"/>
  </inertial>
  <visual>
     <origin xyz="0.010000 -0.000000 0.028500" rpy="-1.57079633 0.00000000 1.57079633"/>
     <geometry>
     <mesh filename="package://robot_assembler/meshes/fr12_h102.dae" scale="1.000000 1.000000 1.000000"/>
     </geometry>
  </visual>
  <collision>
     <origin xyz="0.010000 -0.000000 0.028500" rpy="-1.57079633 0.00000000 1.57079633"/>
     <geometry>
     <mesh filename="package://robot_assembler/meshes/fr12_h102.dae" scale="1.000000 1.000000 1.000000"/>
     </geometry>
  </collision>
  </link>
  <xacro:gazebo_link_reference link_name="LINK1" />
  <link name="LINK1">
  <inertial>
     <mass value="0.212"/>
     <origin rpy="0 0 0" xyz="0.000708 -0.012283 0.001288"/>
     <inertia ixx="0.000132" ixy="-4.245283e-08" ixz="-2.896769e-06" iyy="0.000116" iyz="-2.617925e-07" izz="5.942872e-05"/>
  </inertial>
  <visual>
     <origin xyz="0.000000 0.000000 -0.019000" rpy="0.00000000 0.00000000 0.00000000"/>
     <geometry>
     <mesh filename="package://robot_assembler/meshes/xm430_dynamixel.dae" scale="1.000000 1.000000 1.000000"/>
     </geometry>
  </visual>
  <collision>
     <origin xyz="0.000000 0.000000 -0.019000" rpy="0.00000000 0.00000000 0.00000000"/>
     <geometry>
     <mesh filename="package://robot_assembler/meshes/xm430_dynamixel.dae" scale="1.000000 1.000000 1.000000"/>
     </geometry>
  </collision>
  <visual>
     <origin xyz="0.000000 0.000000 -0.016000" rpy="1.57079633 0.00000000 0.00000000"/>
     <geometry>
     <mesh filename="package://robot_assembler/meshes/fr12_x102.dae" scale="1.000000 1.000000 1.000000"/>
     </geometry>
  </visual>
  <collision>
     <origin xyz="0.000000 0.000000 -0.016000" rpy="1.57079633 0.00000000 0.00000000"/>
     <geometry>
     <mesh filename="package://robot_assembler/meshes/fr12_x102.dae" scale="1.000000 1.000000 1.000000"/>
     </geometry>
  </collision>
  <visual>
     <origin xyz="0.000000 0.000000 0.020600" rpy="-2.30283502 1.57079633 -2.30283502"/>
     <geometry>
     <mesh filename="package://robot_assembler/meshes/xm430_dynamixel.dae" scale="1.000000 1.000000 1.000000"/>
     </geometry>
  </visual>
  <collision>
     <origin xyz="0.000000 0.000000 0.020600" rpy="-2.30283502 1.57079633 -2.30283502"/>
     <geometry>
     <mesh filename="package://robot_assembler/meshes/xm430_dynamixel.dae" scale="1.000000 1.000000 1.000000"/>
     </geometry>
  </collision>
  </link>
  <xacro:gazebo_link_reference link_name="LINK2" />
  <link name="LINK2">
  <inertial>
     <mass value="0.035"/>
     <origin rpy="0 0 0" xyz="7.359193e-17 -0.045207 -0.019"/>
     <inertia ixx="2.398520e-05" ixy="2.345021e-20" ixz="3.195554e-21" iyy="7.029167e-06" iyz="-2.651719e-21" izz="2.676187e-05"/>
  </inertial>
  <visual>
     <origin xyz="0.000000 -0.000000 -0.019000" rpy="-0.04157055 1.57079633 3.10002210"/>
     <geometry>
     <mesh filename="package://robot_assembler/meshes/fr12_h103.dae" scale="1.000000 1.000000 1.000000"/>
     </geometry>
  </visual>
  <collision>
     <origin xyz="0.000000 -0.000000 -0.019000" rpy="-0.04157055 1.57079633 3.10002210"/>
     <geometry>
     <mesh filename="package://robot_assembler/meshes/fr12_h103.dae" scale="1.000000 1.000000 1.000000"/>
     </geometry>
  </collision>
  <visual>
     <origin xyz="0.000000 -0.083000 -0.019000" rpy="2.93438887 1.57079633 2.93438887"/>
     <geometry>
     <mesh filename="package://robot_assembler/meshes/fr12_h101.dae" scale="1.000000 1.000000 1.000000"/>
     </geometry>
  </visual>
  <collision>
     <origin xyz="0.000000 -0.083000 -0.019000" rpy="2.93438887 1.57079633 2.93438887"/>
     <geometry>
     <mesh filename="package://robot_assembler/meshes/fr12_h101.dae" scale="1.000000 1.000000 1.000000"/>
     </geometry>
  </collision>
  </link>
  <xacro:gazebo_link_reference link_name="LINK3" />
  <link name="LINK3">
  <inertial>
     <mass value="0.129"/>
     <origin rpy="0 0 0" xyz="-7.160508e-18 -0.019475 -0.017837"/>
     <inertia ixx="6.363671e-05" ixy="-2.733004e-20" ixz="7.408855e-22" iyy="2.635199e-05" iyz="-1.121221e-06" izz="5.685405e-05"/>
  </inertial>
  <visual>
     <origin xyz="0.000000 -0.000000 -0.019000" rpy="0.00000000 -0.00000000 0.00000000"/>
     <geometry>
     <mesh filename="package://robot_assembler/meshes/xm430_dynamixel.dae" scale="1.000000 1.000000 1.000000"/>
     </geometry>
  </visual>
  <collision>
     <origin xyz="0.000000 -0.000000 -0.019000" rpy="0.00000000 -0.00000000 0.00000000"/>
     <geometry>
     <mesh filename="package://robot_assembler/meshes/xm430_dynamixel.dae" scale="1.000000 1.000000 1.000000"/>
     </geometry>
  </collision>
  <visual>
     <origin xyz="-0.000000 -0.021000 -0.019000" rpy="1.44644133 -1.57079633 0.12435499"/>
     <geometry>
     <mesh filename="package://robot_assembler/meshes/fr12_s102.dae" scale="1.000000 1.000000 1.000000"/>
     </geometry>
  </visual>
  <collision>
     <origin xyz="-0.000000 -0.021000 -0.019000" rpy="1.44644133 -1.57079633 0.12435499"/>
     <geometry>
     <mesh filename="package://robot_assembler/meshes/fr12_s102.dae" scale="1.000000 1.000000 1.000000"/>
     </geometry>
  </collision>
  <visual>
     <origin xyz="-0.000000 -0.068500 -0.019000" rpy="-2.60561900 1.57079633 -2.60561900"/>
     <geometry>
     <mesh filename="package://robot_assembler/meshes/fr12_h101.dae" scale="1.000000 1.000000 1.000000"/>
     </geometry>
  </visual>
  <collision>
     <origin xyz="-0.000000 -0.068500 -0.019000" rpy="-2.60561900 1.57079633 -2.60561900"/>
     <geometry>
     <mesh filename="package://robot_assembler/meshes/fr12_h101.dae" scale="1.000000 1.000000 1.000000"/>
     </geometry>
  </collision>
  </link>
  <xacro:gazebo_link_reference link_name="LINK4" />
  <link name="LINK4">
  <inertial>
     <mass value="0.212"/>
     <origin rpy="0 0 0" xyz="0.019312 -0.015943 -0.018292"/>
     <inertia ixx="6.235702e-05" ixy="1.518764e-05" ixz="2.896769e-06" iyy="0.000116" iyz="-5.915094e-07" izz="0.000135"/>
  </inertial>
  <visual>
     <origin xyz="-0.000000 -0.000000 -0.019000" rpy="0.00000000 0.00000000 0.00000000"/>
     <geometry>
     <mesh filename="package://robot_assembler/meshes/xm430_dynamixel.dae" scale="1.000000 1.000000 1.000000"/>
     </geometry>
  </visual>
  <collision>
     <origin xyz="-0.000000 -0.000000 -0.019000" rpy="0.00000000 0.00000000 0.00000000"/>
     <geometry>
     <mesh filename="package://robot_assembler/meshes/xm430_dynamixel.dae" scale="1.000000 1.000000 1.000000"/>
     </geometry>
  </collision>
  <visual>
     <origin xyz="0.036600 -0.032000 -0.019000" rpy="0.10308161 1.57079633 1.67387794"/>
     <geometry>
     <mesh filename="package://robot_assembler/meshes/fr12_x102.dae" scale="1.000000 1.000000 1.000000"/>
     </geometry>
  </visual>
  <collision>
     <origin xyz="0.036600 -0.032000 -0.019000" rpy="0.10308161 1.57079633 1.67387794"/>
     <geometry>
     <mesh filename="package://robot_assembler/meshes/fr12_x102.dae" scale="1.000000 1.000000 1.000000"/>
     </geometry>
  </collision>
  <visual>
     <origin xyz="0.039600 -0.032000 -0.019000" rpy="-1.33931896 1.57079633 1.80227369"/>
     <geometry>
     <mesh filename="package://robot_assembler/meshes/xm430_dynamixel.dae" scale="1.000000 1.000000 1.000000"/>
     </geometry>
  </visual>
  <collision>
     <origin xyz="0.039600 -0.032000 -0.019000" rpy="-1.33931896 1.57079633 1.80227369"/>
     <geometry>
     <mesh filename="package://robot_assembler/meshes/xm430_dynamixel.dae" scale="1.000000 1.000000 1.000000"/>
     </geometry>
  </collision>
  </link>
  <xacro:gazebo_link_reference link_name="LINK5" />
  <link name="LINK5">
  <inertial>
     <mass value="0.135"/>
     <origin rpy="0 0 0" xyz="-5.789607e-17 0.04568 0.031167"/>
     <inertia ixx="6.146552e-05" ixy="1.048218e-19" ixz="3.449937e-20" iyy="3.497750e-05" iyz="-5.801333e-06" izz="4.753552e-05"/>
  </inertial>
  <visual>
     <origin xyz="0.000000 0.000000 0.020500" rpy="-0.08381691 1.57079633 -0.08381691"/>
     <geometry>
     <mesh filename="package://robot_assembler/meshes/fr12_h101.dae" scale="1.000000 1.000000 1.000000"/>
     </geometry>
  </visual>
  <collision>
     <origin xyz="0.000000 0.000000 0.020500" rpy="-0.08381691 1.57079633 -0.08381691"/>
     <geometry>
     <mesh filename="package://robot_assembler/meshes/fr12_h101.dae" scale="1.000000 1.000000 1.000000"/>
     </geometry>
  </collision>
  <visual>
     <origin xyz="0.000000 0.028000 0.044500" rpy="1.57079633 -0.00000000 0.00000000"/>
     <geometry>
     <mesh filename="package://robot_assembler/meshes/fr12_s103_b.dae" scale="1.000000 1.000000 1.000000"/>
     </geometry>
  </visual>
  <collision>
     <origin xyz="0.000000 0.028000 0.044500" rpy="1.57079633 -0.00000000 0.00000000"/>
     <geometry>
     <mesh filename="package://robot_assembler/meshes/fr12_s103_b.dae" scale="1.000000 1.000000 1.000000"/>
     </geometry>
  </collision>
  <visual>
     <origin xyz="-0.000000 0.050750 0.044500" rpy="1.57079633 0.00000000 -3.14159265"/>
     <geometry>
     <mesh filename="package://robot_assembler/meshes/xm430_dynamixel.dae" scale="1.000000 1.000000 1.000000"/>
     </geometry>
  </visual>
  <collision>
     <origin xyz="-0.000000 0.050750 0.044500" rpy="1.57079633 0.00000000 -3.14159265"/>
     <geometry>
     <mesh filename="package://robot_assembler/meshes/xm430_dynamixel.dae" scale="1.000000 1.000000 1.000000"/>
     </geometry>
  </collision>
  </link>
  <xacro:gazebo_link_reference link_name="LINK6" />
  <link name="LINK6">
  <inertial>
     <mass value="0.148"/>
     <origin rpy="0 0 0" xyz="0.023547 -0.000689 0.021324"/>
     <inertia ixx="7.437909e-05" ixy="-2.377824e-06" ixz="-1.677073e-05" iyy="8.886958e-05" iyz="6.014189e-07" izz="5.708055e-05"/>
  </inertial>
  <visual>
     <origin xyz="0.024000 0.000000 0.019500" rpy="-3.14159265 0.00000000 1.57079633"/>
     <geometry>
     <mesh filename="package://robot_assembler/meshes/fr12_s101.dae" scale="1.000000 1.000000 1.000000"/>
     </geometry>
  </visual>
  <collision>
     <origin xyz="0.024000 0.000000 0.019500" rpy="-3.14159265 0.00000000 1.57079633"/>
     <geometry>
     <mesh filename="package://robot_assembler/meshes/fr12_s101.dae" scale="1.000000 1.000000 1.000000"/>
     </geometry>
  </collision>
  <visual>
     <origin xyz="0.008000 0.000000 0.014250" rpy="2.55359005 1.57079633 -2.15879893"/>
     <geometry>
     <mesh filename="package://robot_assembler/meshes/xm430_dynamixel.dae" scale="1.000000 1.000000 1.000000"/>
     </geometry>
  </visual>
  <collision>
     <origin xyz="0.008000 0.000000 0.014250" rpy="2.55359005 1.57079633 -2.15879893"/>
     <geometry>
     <mesh filename="package://robot_assembler/meshes/xm430_dynamixel.dae" scale="1.000000 1.000000 1.000000"/>
     </geometry>
  </collision>
  <visual>
     <origin xyz="0.029000 0.000000 0.014250" rpy="1.57079633 0.00000000 1.57079633"/>
     <geometry>
     <mesh filename="package://robot_assembler/meshes/fr12_e170.dae" scale="1.000000 1.000000 1.000000"/>
     </geometry>
  </visual>
  <collision>
     <origin xyz="0.029000 0.000000 0.014250" rpy="1.57079633 0.00000000 1.57079633"/>
     <geometry>
     <mesh filename="package://robot_assembler/meshes/fr12_e170.dae" scale="1.000000 1.000000 1.000000"/>
     </geometry>
  </collision>
  </link>
  <xacro:gazebo_link_reference link_name="LINK7" />
  <link name="LINK7">
  <inertial>
     <mass value="0.035"/>
     <origin rpy="0 0 0" xyz="-0.023397 0.018542 -0.019"/>
     <inertia ixx="1.643493e-05" ixy="8.139500e-06" ixz="-1.249029e-22" iyy="2.583362e-05" iyz="-1.373904e-21" izz="2.525856e-05"/>
  </inertial>
  <visual>
     <origin xyz="-0.000000 -0.000000 -0.019000" rpy="-1.54110078 -1.57079633 1.01750200"/>
     <geometry>
     <mesh filename="package://robot_assembler/meshes/fr12_e171.dae" scale="1.000000 1.000000 1.000000"/>
     </geometry>
  </visual>
  <collision>
     <origin xyz="-0.000000 -0.000000 -0.019000" rpy="-1.54110078 -1.57079633 1.01750200"/>
     <geometry>
     <mesh filename="package://robot_assembler/meshes/fr12_e171.dae" scale="1.000000 1.000000 1.000000"/>
     </geometry>
  </collision>
  </link>
  <xacro:gazebo_link_reference link_name="LINK8" />
  <link name="LINK8">
  <inertial>
     <mass value="0.016"/>
     <origin rpy="0 0 0" xyz="-0.01 0.004807 0.0148"/>
     <inertia ixx="3.031831e-06" ixy="1.037836e-22" ixz="-1.474285e-21" iyy="3.409547e-06" iyz="-1.544107e-22" izz="4.104951e-06"/>
  </inertial>
  <visual>
     <origin xyz="-0.010000 -0.000000 0.028500" rpy="-1.57079633 0.00000000 -1.57079633"/>
     <geometry>
     <mesh filename="package://robot_assembler/meshes/fr12_h102.dae" scale="1.000000 1.000000 1.000000"/>
     </geometry>
  </visual>
  <collision>
     <origin xyz="-0.010000 -0.000000 0.028500" rpy="-1.57079633 0.00000000 -1.57079633"/>
     <geometry>
     <mesh filename="package://robot_assembler/meshes/fr12_h102.dae" scale="1.000000 1.000000 1.000000"/>
     </geometry>
  </collision>
  </link>
  <xacro:gazebo_link_reference link_name="LINK9" />
  <link name="LINK9">
  <inertial>
     <mass value="0.212"/>
     <origin rpy="0 0 0" xyz="-0.000708 -0.012283 0.001288"/>
     <inertia ixx="0.000132" ixy="4.245283e-08" ixz="2.896769e-06" iyy="0.000116" iyz="-2.617925e-07" izz="5.942872e-05"/>
  </inertial>
  <visual>
     <origin xyz="-0.000000 0.000000 -0.019000" rpy="0.00000000 -0.00000000 0.00000000"/>
     <geometry>
     <mesh filename="package://robot_assembler/meshes/xm430_dynamixel.dae" scale="1.000000 1.000000 1.000000"/>
     </geometry>
  </visual>
  <collision>
     <origin xyz="-0.000000 0.000000 -0.019000" rpy="0.00000000 -0.00000000 0.00000000"/>
     <geometry>
     <mesh filename="package://robot_assembler/meshes/xm430_dynamixel.dae" scale="1.000000 1.000000 1.000000"/>
     </geometry>
  </collision>
  <visual>
     <origin xyz="0.000000 0.000000 -0.016000" rpy="1.57079633 0.00000000 -0.00000000"/>
     <geometry>
     <mesh filename="package://robot_assembler/meshes/fr12_x102.dae" scale="1.000000 1.000000 1.000000"/>
     </geometry>
  </visual>
  <collision>
     <origin xyz="0.000000 0.000000 -0.016000" rpy="1.57079633 0.00000000 -0.00000000"/>
     <geometry>
     <mesh filename="package://robot_assembler/meshes/fr12_x102.dae" scale="1.000000 1.000000 1.000000"/>
     </geometry>
  </collision>
  <visual>
     <origin xyz="0.000000 0.000000 0.020600" rpy="-0.60136073 -1.57079633 0.60136073"/>
     <geometry>
     <mesh filename="package://robot_assembler/meshes/xm430_dynamixel.dae" scale="1.000000 1.000000 1.000000"/>
     </geometry>
  </visual>
  <collision>
     <origin xyz="0.000000 0.000000 0.020600" rpy="-0.60136073 -1.57079633 0.60136073"/>
     <geometry>
     <mesh filename="package://robot_assembler/meshes/xm430_dynamixel.dae" scale="1.000000 1.000000 1.000000"/>
     </geometry>
  </collision>
  </link>
  <xacro:gazebo_link_reference link_name="LINK10" />
  <link name="LINK10">
  <inertial>
     <mass value="0.035"/>
     <origin rpy="0 0 0" xyz="7.790594e-17 -0.045207 -0.019"/>
     <inertia ixx="2.398520e-05" ixy="2.409884e-20" ixz="3.195554e-21" iyy="7.029167e-06" iyz="5.107245e-21" izz="2.676187e-05"/>
  </inertial>
  <visual>
     <origin xyz="0.000000 0.000000 -0.019000" rpy="-0.14048970 1.57079633 3.00110295"/>
     <geometry>
     <mesh filename="package://robot_assembler/meshes/fr12_h103.dae" scale="1.000000 1.000000 1.000000"/>
     </geometry>
  </visual>
  <collision>
     <origin xyz="0.000000 0.000000 -0.019000" rpy="-0.14048970 1.57079633 3.00110295"/>
     <geometry>
     <mesh filename="package://robot_assembler/meshes/fr12_h103.dae" scale="1.000000 1.000000 1.000000"/>
     </geometry>
  </collision>
  <visual>
     <origin xyz="0.000000 -0.083000 -0.019000" rpy="2.87754125 1.57079633 2.87754125"/>
     <geometry>
     <mesh filename="package://robot_assembler/meshes/fr12_h101.dae" scale="1.000000 1.000000 1.000000"/>
     </geometry>
  </visual>
  <collision>
     <origin xyz="0.000000 -0.083000 -0.019000" rpy="2.87754125 1.57079633 2.87754125"/>
     <geometry>
     <mesh filename="package://robot_assembler/meshes/fr12_h101.dae" scale="1.000000 1.000000 1.000000"/>
     </geometry>
  </collision>
  </link>
  <xacro:gazebo_link_reference link_name="LINK11" />
  <link name="LINK11">
  <inertial>
     <mass value="0.129"/>
     <origin rpy="0 0 0" xyz="-2.203233e-18 -0.019475 -0.017837"/>
     <inertia ixx="6.363671e-05" ixy="-2.237982e-20" ixz="6.325066e-22" iyy="2.635199e-05" iyz="-1.121221e-06" izz="5.685405e-05"/>
  </inertial>
  <visual>
     <origin xyz="0.000000 0.000000 -0.019000" rpy="0.00000000 -0.00000000 0.00000000"/>
     <geometry>
     <mesh filename="package://robot_assembler/meshes/xm430_dynamixel.dae" scale="1.000000 1.000000 1.000000"/>
     </geometry>
  </visual>
  <collision>
     <origin xyz="0.000000 0.000000 -0.019000" rpy="0.00000000 -0.00000000 0.00000000"/>
     <geometry>
     <mesh filename="package://robot_assembler/meshes/xm430_dynamixel.dae" scale="1.000000 1.000000 1.000000"/>
     </geometry>
  </collision>
  <visual>
     <origin xyz="0.000000 -0.021000 -0.019000" rpy="0.78539816 -1.57079633 0.78539816"/>
     <geometry>
     <mesh filename="package://robot_assembler/meshes/fr12_s102.dae" scale="1.000000 1.000000 1.000000"/>
     </geometry>
  </visual>
  <collision>
     <origin xyz="0.000000 -0.021000 -0.019000" rpy="0.78539816 -1.57079633 0.78539816"/>
     <geometry>
     <mesh filename="package://robot_assembler/meshes/fr12_s102.dae" scale="1.000000 1.000000 1.000000"/>
     </geometry>
  </collision>
  <visual>
     <origin xyz="-0.000000 -0.068500 -0.019000" rpy="-2.52611294 1.57079633 -2.52611294"/>
     <geometry>
     <mesh filename="package://robot_assembler/meshes/fr12_h101.dae" scale="1.000000 1.000000 1.000000"/>
     </geometry>
  </visual>
  <collision>
     <origin xyz="-0.000000 -0.068500 -0.019000" rpy="-2.52611294 1.57079633 -2.52611294"/>
     <geometry>
     <mesh filename="package://robot_assembler/meshes/fr12_h101.dae" scale="1.000000 1.000000 1.000000"/>
     </geometry>
  </collision>
  </link>
  <xacro:gazebo_link_reference link_name="LINK12" />
  <link name="LINK12">
  <inertial>
     <mass value="0.212"/>
     <origin rpy="0 0 0" xyz="-0.019312 -0.015943 -0.018292"/>
     <inertia ixx="6.235702e-05" ixy="-1.518764e-05" ixz="-2.896769e-06" iyy="0.000116" iyz="-5.915094e-07" izz="0.000135"/>
  </inertial>
  <visual>
     <origin xyz="0.000000 0.000000 -0.019000" rpy="0.00000000 -0.00000000 0.00000000"/>
     <geometry>
     <mesh filename="package://robot_assembler/meshes/xm430_dynamixel.dae" scale="1.000000 1.000000 1.000000"/>
     </geometry>
  </visual>
  <collision>
     <origin xyz="0.000000 0.000000 -0.019000" rpy="0.00000000 -0.00000000 0.00000000"/>
     <geometry>
     <mesh filename="package://robot_assembler/meshes/xm430_dynamixel.dae" scale="1.000000 1.000000 1.000000"/>
     </geometry>
  </collision>
  <visual>
     <origin xyz="-0.036600 -0.032000 -0.019000" rpy="-2.55359005 -1.57079633 0.98279372"/>
     <geometry>
     <mesh filename="package://robot_assembler/meshes/fr12_x102.dae" scale="1.000000 1.000000 1.000000"/>
     </geometry>
  </visual>
  <collision>
     <origin xyz="-0.036600 -0.032000 -0.019000" rpy="-2.55359005 -1.57079633 0.98279372"/>
     <geometry>
     <mesh filename="package://robot_assembler/meshes/fr12_x102.dae" scale="1.000000 1.000000 1.000000"/>
     </geometry>
  </collision>
  <visual>
     <origin xyz="-0.039600 -0.032000 -0.019000" rpy="2.08560228 -1.57079633 1.05599037"/>
     <geometry>
     <mesh filename="package://robot_assembler/meshes/xm430_dynamixel.dae" scale="1.000000 1.000000 1.000000"/>
     </geometry>
  </visual>
  <collision>
     <origin xyz="-0.039600 -0.032000 -0.019000" rpy="2.08560228 -1.57079633 1.05599037"/>
     <geometry>
     <mesh filename="package://robot_assembler/meshes/xm430_dynamixel.dae" scale="1.000000 1.000000 1.000000"/>
     </geometry>
  </collision>
  </link>
  <xacro:gazebo_link_reference link_name="LINK13" />
  <link name="LINK13">
  <inertial>
     <mass value="0.135"/>
     <origin rpy="0 0 0" xyz="-1.168448e-16 0.04568 0.031167"/>
     <inertia ixx="6.146552e-05" ixy="1.021910e-19" ixz="3.124761e-20" iyy="3.497750e-05" iyz="-5.801333e-06" izz="4.753552e-05"/>
  </inertial>
  <visual>
     <origin xyz="-0.000000 0.000000 0.020500" rpy="-0.03647142 1.57079633 -0.03647142"/>
     <geometry>
     <mesh filename="package://robot_assembler/meshes/fr12_h101.dae" scale="1.000000 1.000000 1.000000"/>
     </geometry>
  </visual>
  <collision>
     <origin xyz="-0.000000 0.000000 0.020500" rpy="-0.03647142 1.57079633 -0.03647142"/>
     <geometry>
     <mesh filename="package://robot_assembler/meshes/fr12_h101.dae" scale="1.000000 1.000000 1.000000"/>
     </geometry>
  </collision>
  <visual>
     <origin xyz="-0.000000 0.028000 0.044500" rpy="1.57079633 -0.00000000 0.00000000"/>
     <geometry>
     <mesh filename="package://robot_assembler/meshes/fr12_s103_b.dae" scale="1.000000 1.000000 1.000000"/>
     </geometry>
  </visual>
  <collision>
     <origin xyz="-0.000000 0.028000 0.044500" rpy="1.57079633 -0.00000000 0.00000000"/>
     <geometry>
     <mesh filename="package://robot_assembler/meshes/fr12_s103_b.dae" scale="1.000000 1.000000 1.000000"/>
     </geometry>
  </collision>
  <visual>
     <origin xyz="-0.000000 0.050750 0.044500" rpy="1.57079633 0.00000000 -3.14159265"/>
     <geometry>
     <mesh filename="package://robot_assembler/meshes/xm430_dynamixel.dae" scale="1.000000 1.000000 1.000000"/>
     </geometry>
  </visual>
  <collision>
     <origin xyz="-0.000000 0.050750 0.044500" rpy="1.57079633 0.00000000 -3.14159265"/>
     <geometry>
     <mesh filename="package://robot_assembler/meshes/xm430_dynamixel.dae" scale="1.000000 1.000000 1.000000"/>
     </geometry>
  </collision>
  </link>
  <xacro:gazebo_link_reference link_name="LINK14" />
  <link name="LINK14">
  <inertial>
     <mass value="0.148"/>
     <origin rpy="0 0 0" xyz="-0.023547 0.002716 0.021324"/>
     <inertia ixx="7.335746e-05" ixy="-3.442014e-06" ixz="1.677073e-05" iyy="8.886958e-05" iyz="1.520878e-06" izz="5.605893e-05"/>
  </inertial>
  <visual>
     <origin xyz="-0.024000 -0.000000 0.019500" rpy="-3.14159265 0.00000000 -1.57079633"/>
     <geometry>
     <mesh filename="package://robot_assembler/meshes/fr12_s101.dae" scale="1.000000 1.000000 1.000000"/>
     </geometry>
  </visual>
  <collision>
     <origin xyz="-0.024000 -0.000000 0.019500" rpy="-3.14159265 0.00000000 -1.57079633"/>
     <geometry>
     <mesh filename="package://robot_assembler/meshes/fr12_s101.dae" scale="1.000000 1.000000 1.000000"/>
     </geometry>
  </collision>
  <visual>
     <origin xyz="-0.008000 -0.000000 0.014250" rpy="2.35619449 -1.57079633 2.35619449"/>
     <geometry>
     <mesh filename="package://robot_assembler/meshes/xm430_dynamixel.dae" scale="1.000000 1.000000 1.000000"/>
     </geometry>
  </visual>
  <collision>
     <origin xyz="-0.008000 -0.000000 0.014250" rpy="2.35619449 -1.57079633 2.35619449"/>
     <geometry>
     <mesh filename="package://robot_assembler/meshes/xm430_dynamixel.dae" scale="1.000000 1.000000 1.000000"/>
     </geometry>
  </collision>
  <visual>
     <origin xyz="-0.029000 0.000000 0.014250" rpy="1.57079633 -0.00000000 -1.57079633"/>
     <geometry>
     <mesh filename="package://robot_assembler/meshes/fr12_e170.dae" scale="1.000000 1.000000 1.000000"/>
     </geometry>
  </visual>
  <collision>
     <origin xyz="-0.029000 0.000000 0.014250" rpy="1.57079633 -0.00000000 -1.57079633"/>
     <geometry>
     <mesh filename="package://robot_assembler/meshes/fr12_e170.dae" scale="1.000000 1.000000 1.000000"/>
     </geometry>
  </collision>
  </link>
  <xacro:gazebo_link_reference link_name="LINK15" />
  <link name="LINK15">
  <inertial>
     <mass value="0.035"/>
     <origin rpy="0 0 0" xyz="0.023397 0.018542 -0.019"/>
     <inertia ixx="1.643493e-05" ixy="-8.139500e-06" ixz="-2.022285e-21" iyy="2.583362e-05" iyz="-1.044581e-21" izz="2.525856e-05"/>
  </inertial>
  <visual>
     <origin xyz="0.000000 -0.000000 -0.019000" rpy="-0.05995117 1.57079633 0.46364761"/>
     <geometry>
     <mesh filename="package://robot_assembler/meshes/fr12_e171.dae" scale="1.000000 1.000000 1.000000"/>
     </geometry>
  </visual>
  <collision>
     <origin xyz="0.000000 -0.000000 -0.019000" rpy="-0.05995117 1.57079633 0.46364761"/>
     <geometry>
     <mesh filename="package://robot_assembler/meshes/fr12_e171.dae" scale="1.000000 1.000000 1.000000"/>
     </geometry>
  </collision>
  </link>
  <xacro:gazebo_link_reference link_name="LINK16" />
  <link name="LINK16">
  <inertial>
     <mass value="0.015"/>
     <origin rpy="0 0 0" xyz="-2.131628e-17 -1.776357e-18 0.01455"/>
     <inertia ixx="1.969763e-06" ixy="-7.473640e-22" ixz="-1.473474e-21" iyy="3.159763e-06" iyz="4.904843e-23" izz="3.012500e-06"/>
  </inertial>
  <visual>
     <origin xyz="-0.000000 -0.000000 0.028000" rpy="-1.57079633 0.00000000 -1.57079633"/>
     <geometry>
     <mesh filename="package://robot_assembler/meshes/fr12_h101.dae" scale="1.000000 1.000000 1.000000"/>
     </geometry>
  </visual>
  <collision>
     <origin xyz="-0.000000 -0.000000 0.028000" rpy="-1.57079633 0.00000000 -1.57079633"/>
     <geometry>
     <mesh filename="package://robot_assembler/meshes/fr12_h101.dae" scale="1.000000 1.000000 1.000000"/>
     </geometry>
  </collision>
  </link>
  <xacro:gazebo_link_reference link_name="LINK17" />
  <link name="LINK17">
  <inertial>
     <mass value="0.34"/>
     <origin rpy="0 0 0" xyz="0.000441 -0.031288 -0.005909"/>
     <inertia ixx="0.000419" ixy="-2.893235e-06" ixz="-3.976279e-06" iyy="0.000171" iyz="-7.634836e-05" izz="0.000308"/>
  </inertial>
  <visual>
     <origin xyz="0.000000 0.000000 -0.019000" rpy="0.00000000 -0.00000000 0.00000000"/>
     <geometry>
     <mesh filename="package://robot_assembler/meshes/xm430_dynamixel.dae" scale="1.000000 1.000000 1.000000"/>
     </geometry>
  </visual>
  <collision>
     <origin xyz="0.000000 0.000000 -0.019000" rpy="0.00000000 -0.00000000 0.00000000"/>
     <geometry>
     <mesh filename="package://robot_assembler/meshes/xm430_dynamixel.dae" scale="1.000000 1.000000 1.000000"/>
     </geometry>
  </collision>
  <visual>
     <origin xyz="-0.000000 0.000000 -0.016000" rpy="1.57079633 -0.00000000 0.00000000"/>
     <geometry>
     <mesh filename="package://robot_assembler/meshes/fr12_x102.dae" scale="1.000000 1.000000 1.000000"/>
     </geometry>
  </visual>
  <collision>
     <origin xyz="-0.000000 0.000000 -0.016000" rpy="1.57079633 -0.00000000 0.00000000"/>
     <geometry>
     <mesh filename="package://robot_assembler/meshes/fr12_x102.dae" scale="1.000000 1.000000 1.000000"/>
     </geometry>
  </collision>
  <visual>
     <origin xyz="0.000000 0.000000 0.020600" rpy="-2.88816299 1.57079633 -2.88816299"/>
     <geometry>
     <mesh filename="package://robot_assembler/meshes/xm430_dynamixel.dae" scale="1.000000 1.000000 1.000000"/>
     </geometry>
  </visual>
  <collision>
     <origin xyz="0.000000 0.000000 0.020600" rpy="-2.88816299 1.57079633 -2.88816299"/>
     <geometry>
     <mesh filename="package://robot_assembler/meshes/xm430_dynamixel.dae" scale="1.000000 1.000000 1.000000"/>
     </geometry>
  </collision>
  <visual>
     <origin xyz="-0.000000 -0.021000 -0.019000" rpy="2.03444394 1.57079633 0.46364761"/>
     <geometry>
     <mesh filename="package://robot_assembler/meshes/fr12_s102.dae" scale="1.000000 1.000000 1.000000"/>
     </geometry>
  </visual>
  <collision>
     <origin xyz="-0.000000 -0.021000 -0.019000" rpy="2.03444394 1.57079633 0.46364761"/>
     <geometry>
     <mesh filename="package://robot_assembler/meshes/fr12_s102.dae" scale="1.000000 1.000000 1.000000"/>
     </geometry>
  </collision>
  <visual>
     <origin xyz="-0.000000 -0.060000 -0.019000" rpy="-2.46685171 1.57079633 -0.89605538"/>
     <geometry>
     <mesh filename="package://robot_assembler/meshes/fr12_s102.dae" scale="1.000000 1.000000 1.000000"/>
     </geometry>
  </visual>
  <collision>
     <origin xyz="-0.000000 -0.060000 -0.019000" rpy="-2.46685171 1.57079633 -0.89605538"/>
     <geometry>
     <mesh filename="package://robot_assembler/meshes/fr12_s102.dae" scale="1.000000 1.000000 1.000000"/>
     </geometry>
  </collision>
  <visual>
     <origin xyz="-0.000000 -0.081000 -0.019000" rpy="0.00000000 0.00000000 3.14159265"/>
     <geometry>
     <mesh filename="package://robot_assembler/meshes/xm430_dynamixel.dae" scale="1.000000 1.000000 1.000000"/>
     </geometry>
  </visual>
  <collision>
     <origin xyz="-0.000000 -0.081000 -0.019000" rpy="0.00000000 0.00000000 3.14159265"/>
     <geometry>
     <mesh filename="package://robot_assembler/meshes/xm430_dynamixel.dae" scale="1.000000 1.000000 1.000000"/>
     </geometry>
  </collision>
  </link>
  <xacro:gazebo_link_reference link_name="LINK18" />
  <link name="LINK18">
  <inertial>
     <mass value="0.246"/>
     <origin rpy="0 0 0" xyz="-0.058678 -0.053095 -0.01839"/>
     <inertia ixx="0.000153" ixy="-1.008525e-05" ixz="2.045314e-06" iyy="0.00011" iyz="-1.701735e-06" izz="0.000214"/>
  </inertial>
  <visual>
     <origin xyz="0.000000 0.000000 -0.019000" rpy="-0.26299638 1.57079633 1.83139872"/>
     <geometry>
     <mesh filename="package://robot_assembler/meshes/fr12_h103.dae" scale="1.000000 1.000000 1.000000"/>
     </geometry>
  </visual>
  <collision>
     <origin xyz="0.000000 0.000000 -0.019000" rpy="-0.26299638 1.57079633 1.83139872"/>
     <geometry>
     <mesh filename="package://robot_assembler/meshes/fr12_h103.dae" scale="1.000000 1.000000 1.000000"/>
     </geometry>
  </collision>
  <visual>
     <origin xyz="-0.064519 -0.037250 -0.019000" rpy="-0.37667599 -1.57079633 -2.24131788"/>
     <geometry>
     <mesh filename="package://robot_assembler/meshes/fr12_s102.dae" scale="1.000000 1.000000 1.000000"/>
     </geometry>
  </visual>
  <collision>
     <origin xyz="-0.064519 -0.037250 -0.019000" rpy="-0.37667599 -1.57079633 -2.24131788"/>
     <geometry>
     <mesh filename="package://robot_assembler/meshes/fr12_s102.dae" scale="1.000000 1.000000 1.000000"/>
     </geometry>
  </collision>
  <visual>
     <origin xyz="-0.082705 -0.047750 -0.019000" rpy="-0.00000000 -0.00000000 2.09439510"/>
     <geometry>
     <mesh filename="package://robot_assembler/meshes/xm430_dynamixel.dae" scale="1.000000 1.000000 1.000000"/>
     </geometry>
  </visual>
  <collision>
     <origin xyz="-0.082705 -0.047750 -0.019000" rpy="-0.00000000 -0.00000000 2.09439510"/>
     <geometry>
     <mesh filename="package://robot_assembler/meshes/xm430_dynamixel.dae" scale="1.000000 1.000000 1.000000"/>
     </geometry>
  </collision>
  <visual>
     <origin xyz="-0.064405 -0.079447 -0.019000" rpy="0.48163157 1.57079633 1.00523035"/>
     <geometry>
     <mesh filename="package://robot_assembler/meshes/fr12_x102.dae" scale="1.000000 1.000000 1.000000"/>
     </geometry>
  </visual>
  <collision>
     <origin xyz="-0.064405 -0.079447 -0.019000" rpy="0.48163157 1.57079633 1.00523035"/>
     <geometry>
     <mesh filename="package://robot_assembler/meshes/fr12_x102.dae" scale="1.000000 1.000000 1.000000"/>
     </geometry>
  </collision>
  <visual>
     <origin xyz="-0.062905 -0.082045 -0.019000" rpy="-1.11160138 1.57079633 0.98279372"/>
     <geometry>
     <mesh filename="package://robot_assembler/meshes/xm430_dynamixel.dae" scale="1.000000 1.000000 1.000000"/>
     </geometry>
  </visual>
  <collision>
     <origin xyz="-0.062905 -0.082045 -0.019000" rpy="-1.11160138 1.57079633 0.98279372"/>
     <geometry>
     <mesh filename="package://robot_assembler/meshes/xm430_dynamixel.dae" scale="1.000000 1.000000 1.000000"/>
     </geometry>
  </collision>
  </link>
  <xacro:gazebo_link_reference link_name="LINK19" />
  <link name="LINK19">
  <inertial>
     <mass value="0.115"/>
     <origin rpy="0 0 0" xyz="0.001304 0.04632 -0.019"/>
     <inertia ixx="4.539431e-05" ixy="-7.395652e-07" ixz="-2.163587e-21" iyy="2.381893e-05" iyz="-1.489632e-20" izz="5.385323e-05"/>
  </inertial>
  <visual>
     <origin xyz="0.000000 0.000000 -0.019000" rpy="-0.27564280 1.57079633 -0.27564280"/>
     <geometry>
     <mesh filename="package://robot_assembler/meshes/fr12_h101.dae" scale="1.000000 1.000000 1.000000"/>
     </geometry>
  </visual>
  <collision>
     <origin xyz="0.000000 0.000000 -0.019000" rpy="-0.27564280 1.57079633 -0.27564280"/>
     <geometry>
     <mesh filename="package://robot_assembler/meshes/fr12_h101.dae" scale="1.000000 1.000000 1.000000"/>
     </geometry>
  </collision>
  <visual>
     <origin xyz="-0.000000 0.063250 -0.019000" rpy="0.33983691 1.57079633 0.33983691"/>
     <geometry>
     <mesh filename="package://robot_assembler/meshes/xm430_dynamixel.dae" scale="1.000000 1.000000 1.000000"/>
     </geometry>
  </visual>
  <collision>
     <origin xyz="-0.000000 0.063250 -0.019000" rpy="0.33983691 1.57079633 0.33983691"/>
     <geometry>
     <mesh filename="package://robot_assembler/meshes/xm430_dynamixel.dae" scale="1.000000 1.000000 1.000000"/>
     </geometry>
  </collision>
  </link>
  <xacro:gazebo_link_reference link_name="LINK20" />
  <link name="LINK20">
  <inertial>
     <mass value="0.10"/>
     <origin rpy="0 0 0" xyz="-0.05 -0.0485 0.022"/>
     <inertia ixx="3.202708e-05" ixy="1.438816e-21" ixz="4.695043e-22" iyy="2.478750e-05" iyz="1.780984e-21" izz="2.077708e-05"/>
  </inertial>
  <visual>
     <origin xyz="-0.050000 -0.050000 0.010000" rpy="-1.57079633 -0.00000000 0.00000000"/>
     <geometry>
     <mesh filename="package://robot_assembler/meshes/wheel.dae" scale="0.001000 0.001000 0.001000"/>
     </geometry>
  </visual>
  <collision>
     <origin xyz="-0.050000 -0.050000 0.010000" rpy="-1.57079633 -0.00000000 0.00000000"/>
     <geometry>
     <mesh filename="package://robot_assembler/meshes/wheel.dae" scale="0.001000 0.001000 0.001000"/>
     </geometry>
  </collision>
  </link>
  <xacro:gazebo_link_reference link_name="LINK21" />
  <link name="LINK21">
  <inertial>
     <mass value="0.115"/>
     <origin rpy="0 0 0" xyz="0.001304 0.04632 -0.019"/>
     <inertia ixx="4.539431e-05" ixy="-7.395652e-07" ixz="-8.841303e-21" iyy="2.381893e-05" iyz="1.766354e-21" izz="5.385323e-05"/>
  </inertial>
  <visual>
     <origin xyz="0.000000 0.000000 -0.019000" rpy="-0.00000000 1.57079633 -0.00000000"/>
     <geometry>
     <mesh filename="package://robot_assembler/meshes/fr12_h101.dae" scale="1.000000 1.000000 1.000000"/>
     </geometry>
  </visual>
  <collision>
     <origin xyz="0.000000 0.000000 -0.019000" rpy="-0.00000000 1.57079633 -0.00000000"/>
     <geometry>
     <mesh filename="package://robot_assembler/meshes/fr12_h101.dae" scale="1.000000 1.000000 1.000000"/>
     </geometry>
  </collision>
  <visual>
     <origin xyz="-0.000000 0.063250 -0.019000" rpy="-0.12786347 1.57079633 -0.12786347"/>
     <geometry>
     <mesh filename="package://robot_assembler/meshes/xm430_dynamixel.dae" scale="1.000000 1.000000 1.000000"/>
     </geometry>
  </visual>
  <collision>
     <origin xyz="-0.000000 0.063250 -0.019000" rpy="-0.12786347 1.57079633 -0.12786347"/>
     <geometry>
     <mesh filename="package://robot_assembler/meshes/xm430_dynamixel.dae" scale="1.000000 1.000000 1.000000"/>
     </geometry>
  </collision>
  </link>
  <xacro:gazebo_link_reference link_name="LINK22" />
  <link name="LINK22">
  <inertial>
     <mass value="0.10"/>
     <origin rpy="0 0 0" xyz="-0.05 -0.0485 0.022"/>
     <inertia ixx="3.202708e-05" ixy="-4.543839e-35" ixz="1.514613e-35" iyy="2.478750e-05" iyz="2.894099e-21" izz="2.077708e-05"/>
  </inertial>
  <visual>
     <origin xyz="-0.050000 -0.050000 0.010000" rpy="-1.57079633 0.00000000 0.00000000"/>
     <geometry>
     <mesh filename="package://robot_assembler/meshes/wheel.dae" scale="0.001000 0.001000 0.001000"/>
     </geometry>
  </visual>
  <collision>
     <origin xyz="-0.050000 -0.050000 0.010000" rpy="-1.57079633 0.00000000 0.00000000"/>
     <geometry>
     <mesh filename="package://robot_assembler/meshes/wheel.dae" scale="0.001000 0.001000 0.001000"/>
     </geometry>
  </collision>
  </link>
  <xacro:gazebo_link_reference link_name="LINK23" />
  <link name="LINK23">
  <inertial>
     <mass value="0.015"/>
     <origin rpy="0 0 0" xyz="-2.131628e-17 -1.776357e-18 0.01455"/>
     <inertia ixx="1.969763e-06" ixy="-7.473640e-22" ixz="-1.473474e-21" iyy="3.159763e-06" iyz="4.904843e-23" izz="3.012500e-06"/>
  </inertial>
  <visual>
     <origin xyz="-0.000000 -0.000000 0.028000" rpy="-1.57079633 0.00000000 -1.57079633"/>
     <geometry>
     <mesh filename="package://robot_assembler/meshes/fr12_h101.dae" scale="1.000000 1.000000 1.000000"/>
     </geometry>
  </visual>
  <collision>
     <origin xyz="-0.000000 -0.000000 0.028000" rpy="-1.57079633 0.00000000 -1.57079633"/>
     <geometry>
     <mesh filename="package://robot_assembler/meshes/fr12_h101.dae" scale="1.000000 1.000000 1.000000"/>
     </geometry>
  </collision>
  </link>
  <xacro:gazebo_link_reference link_name="LINK24" />
  <link name="LINK24">
  <inertial>
     <mass value="0.354"/>
     <origin rpy="0 0 0" xyz="-0.000424 -0.031425 -0.00486"/>
     <inertia ixx="0.000429" ixy="2.913771e-06" ixz="3.819025e-06" iyy="0.000183" iyz="-7.511444e-05" izz="0.00031"/>
  </inertial>
  <visual>
     <origin xyz="0.000000 0.000000 -0.019000" rpy="0.00000000 -0.00000000 0.00000000"/>
     <geometry>
     <mesh filename="package://robot_assembler/meshes/xm430_dynamixel.dae" scale="1.000000 1.000000 1.000000"/>
     </geometry>
  </visual>
  <collision>
     <origin xyz="0.000000 0.000000 -0.019000" rpy="0.00000000 -0.00000000 0.00000000"/>
     <geometry>
     <mesh filename="package://robot_assembler/meshes/xm430_dynamixel.dae" scale="1.000000 1.000000 1.000000"/>
     </geometry>
  </collision>
  <visual>
     <origin xyz="0.000000 0.000000 -0.016000" rpy="1.57079633 -0.00000000 0.00000000"/>
     <geometry>
     <mesh filename="package://robot_assembler/meshes/fr12_x102.dae" scale="1.000000 1.000000 1.000000"/>
     </geometry>
  </visual>
  <collision>
     <origin xyz="0.000000 0.000000 -0.016000" rpy="1.57079633 -0.00000000 0.00000000"/>
     <geometry>
     <mesh filename="package://robot_assembler/meshes/fr12_x102.dae" scale="1.000000 1.000000 1.000000"/>
     </geometry>
  </collision>
  <visual>
     <origin xyz="-0.000000 0.000000 0.020600" rpy="-1.11791708 -1.57079633 1.11791708"/>
     <geometry>
     <mesh filename="package://robot_assembler/meshes/xm430_dynamixel.dae" scale="1.000000 1.000000 1.000000"/>
     </geometry>
  </visual>
  <collision>
     <origin xyz="-0.000000 0.000000 0.020600" rpy="-1.11791708 -1.57079633 1.11791708"/>
     <geometry>
     <mesh filename="package://robot_assembler/meshes/xm430_dynamixel.dae" scale="1.000000 1.000000 1.000000"/>
     </geometry>
  </collision>
  <visual>
     <origin xyz="0.000000 -0.021000 0.020600" rpy="1.57079633 -0.00000000 0.00000000"/>
     <geometry>
     <mesh filename="package://robot_assembler/meshes/fr12_s102.dae" scale="1.000000 1.000000 1.000000"/>
     </geometry>
  </visual>
  <collision>
     <origin xyz="0.000000 -0.021000 0.020600" rpy="1.57079633 -0.00000000 0.00000000"/>
     <geometry>
     <mesh filename="package://robot_assembler/meshes/fr12_s102.dae" scale="1.000000 1.000000 1.000000"/>
     </geometry>
  </collision>
  <visual>
     <origin xyz="0.000000 -0.021000 -0.019000" rpy="0.78539816 -1.57079633 0.78539816"/>
     <geometry>
     <mesh filename="package://robot_assembler/meshes/fr12_s102.dae" scale="1.000000 1.000000 1.000000"/>
     </geometry>
  </visual>
  <collision>
     <origin xyz="0.000000 -0.021000 -0.019000" rpy="0.78539816 -1.57079633 0.78539816"/>
     <geometry>
     <mesh filename="package://robot_assembler/meshes/fr12_s102.dae" scale="1.000000 1.000000 1.000000"/>
     </geometry>
  </collision>
  <visual>
     <origin xyz="0.000000 -0.060000 -0.019000" rpy="0.00000000 -1.57079633 -1.57079633"/>
     <geometry>
     <mesh filename="package://robot_assembler/meshes/fr12_s102.dae" scale="1.000000 1.000000 1.000000"/>
     </geometry>
  </visual>
  <collision>
     <origin xyz="0.000000 -0.060000 -0.019000" rpy="0.00000000 -1.57079633 -1.57079633"/>
     <geometry>
     <mesh filename="package://robot_assembler/meshes/fr12_s102.dae" scale="1.000000 1.000000 1.000000"/>
     </geometry>
  </collision>
  <visual>
     <origin xyz="0.000000 -0.081000 -0.019000" rpy="-0.00000000 -0.00000000 -3.14159265"/>
     <geometry>
     <mesh filename="package://robot_assembler/meshes/xm430_dynamixel.dae" scale="1.000000 1.000000 1.000000"/>
     </geometry>
  </visual>
  <collision>
     <origin xyz="0.000000 -0.081000 -0.019000" rpy="-0.00000000 -0.00000000 -3.14159265"/>
     <geometry>
     <mesh filename="package://robot_assembler/meshes/xm430_dynamixel.dae" scale="1.000000 1.000000 1.000000"/>
     </geometry>
  </collision>
  </link>
  <xacro:gazebo_link_reference link_name="LINK25" />
  <link name="LINK25">
  <inertial>
     <mass value="0.246"/>
     <origin rpy="0 0 0" xyz="0.058678 -0.053095 -0.01839"/>
     <inertia ixx="0.000153" ixy="1.008525e-05" ixz="-2.045314e-06" iyy="0.00011" iyz="-1.701735e-06" izz="0.000214"/>
  </inertial>
  <visual>
     <origin xyz="-0.000000 0.000000 -0.019000" rpy="0.18057484 1.57079633 -1.91382027"/>
     <geometry>
     <mesh filename="package://robot_assembler/meshes/fr12_h103.dae" scale="1.000000 1.000000 1.000000"/>
     </geometry>
  </visual>
  <collision>
     <origin xyz="-0.000000 0.000000 -0.019000" rpy="0.18057484 1.57079633 -1.91382027"/>
     <geometry>
     <mesh filename="package://robot_assembler/meshes/fr12_h103.dae" scale="1.000000 1.000000 1.000000"/>
     </geometry>
  </collision>
  <visual>
     <origin xyz="0.064519 -0.037250 -0.019000" rpy="-0.34554545 -1.57079633 -0.17805332"/>
     <geometry>
     <mesh filename="package://robot_assembler/meshes/fr12_s102.dae" scale="1.000000 1.000000 1.000000"/>
     </geometry>
  </visual>
  <collision>
     <origin xyz="0.064519 -0.037250 -0.019000" rpy="-0.34554545 -1.57079633 -0.17805332"/>
     <geometry>
     <mesh filename="package://robot_assembler/meshes/fr12_s102.dae" scale="1.000000 1.000000 1.000000"/>
     </geometry>
  </collision>
  <visual>
     <origin xyz="0.082705 -0.047750 -0.019000" rpy="-0.00000000 -0.00000000 -2.09439510"/>
     <geometry>
     <mesh filename="package://robot_assembler/meshes/xm430_dynamixel.dae" scale="1.000000 1.000000 1.000000"/>
     </geometry>
  </visual>
  <collision>
     <origin xyz="0.082705 -0.047750 -0.019000" rpy="-0.00000000 -0.00000000 -2.09439510"/>
     <geometry>
     <mesh filename="package://robot_assembler/meshes/xm430_dynamixel.dae" scale="1.000000 1.000000 1.000000"/>
     </geometry>
  </collision>
  <visual>
     <origin xyz="0.064405 -0.079447 -0.019000" rpy="-1.12857429 -1.57079633 0.60497551"/>
     <geometry>
     <mesh filename="package://robot_assembler/meshes/fr12_x102.dae" scale="1.000000 1.000000 1.000000"/>
     </geometry>
  </visual>
  <collision>
     <origin xyz="0.064405 -0.079447 -0.019000" rpy="-1.12857429 -1.57079633 0.60497551"/>
     <geometry>
     <mesh filename="package://robot_assembler/meshes/fr12_x102.dae" scale="1.000000 1.000000 1.000000"/>
     </geometry>
  </collision>
  <visual>
     <origin xyz="0.062905 -0.082045 -0.019000" rpy="-2.70629754 -1.57079633 0.61190243"/>
     <geometry>
     <mesh filename="package://robot_assembler/meshes/xm430_dynamixel.dae" scale="1.000000 1.000000 1.000000"/>
     </geometry>
  </visual>
  <collision>
     <origin xyz="0.062905 -0.082045 -0.019000" rpy="-2.70629754 -1.57079633 0.61190243"/>
     <geometry>
     <mesh filename="package://robot_assembler/meshes/xm430_dynamixel.dae" scale="1.000000 1.000000 1.000000"/>
     </geometry>
  </collision>
  </link>
  <xacro:gazebo_link_reference link_name="LINK26" />
  <link name="LINK26">
  <inertial>
     <mass value="0.115"/>
     <origin rpy="0 0 0" xyz="-0.001304 0.04632 -0.019"/>
     <inertia ixx="4.539431e-05" ixy="7.395652e-07" ixz="-8.714796e-21" iyy="2.381893e-05" iyz="2.228563e-20" izz="5.385323e-05"/>
  </inertial>
  <visual>
     <origin xyz="0.000000 0.000000 -0.019000" rpy="0.16486786 1.57079633 0.16486786"/>
     <geometry>
     <mesh filename="package://robot_assembler/meshes/fr12_h101.dae" scale="1.000000 1.000000 1.000000"/>
     </geometry>
  </visual>
  <collision>
     <origin xyz="0.000000 0.000000 -0.019000" rpy="0.16486786 1.57079633 0.16486786"/>
     <geometry>
     <mesh filename="package://robot_assembler/meshes/fr12_h101.dae" scale="1.000000 1.000000 1.000000"/>
     </geometry>
  </collision>
  <visual>
     <origin xyz="-0.000000 0.063250 -0.019000" rpy="2.49892323 -1.57079633 -2.49892323"/>
     <geometry>
     <mesh filename="package://robot_assembler/meshes/xm430_dynamixel.dae" scale="1.000000 1.000000 1.000000"/>
     </geometry>
  </visual>
  <collision>
     <origin xyz="-0.000000 0.063250 -0.019000" rpy="2.49892323 -1.57079633 -2.49892323"/>
     <geometry>
     <mesh filename="package://robot_assembler/meshes/xm430_dynamixel.dae" scale="1.000000 1.000000 1.000000"/>
     </geometry>
  </collision>
  </link>
  <xacro:gazebo_link_reference link_name="LINK27" />
  <link name="LINK27">
  <inertial>
     <mass value="0.10"/>
     <origin rpy="0 0 0" xyz="-0.05 -0.0485 0.022"/>
     <inertia ixx="3.202708e-05" ixy="-7.376343e-22" ixz="-6.201017e-22" iyy="2.478750e-05" iyz="1.335738e-21" izz="2.077708e-05"/>
  </inertial>
  <visual>
     <origin xyz="-0.050000 -0.050000 0.010000" rpy="-1.57079633 0.00000000 -0.00000000"/>
     <geometry>
     <mesh filename="package://robot_assembler/meshes/wheel.dae" scale="0.001000 0.001000 0.001000"/>
     </geometry>
  </visual>
  <collision>
     <origin xyz="-0.050000 -0.050000 0.010000" rpy="-1.57079633 0.00000000 -0.00000000"/>
     <geometry>
     <mesh filename="package://robot_assembler/meshes/wheel.dae" scale="0.001000 0.001000 0.001000"/>
     </geometry>
  </collision>
  </link>
  <xacro:gazebo_link_reference link_name="LINK28" />
  <link name="LINK28">
  <inertial>
     <mass value="0.115"/>
     <origin rpy="0 0 0" xyz="-0.001304 0.04632 -0.019"/>
     <inertia ixx="4.539431e-05" ixy="7.395652e-07" ixz="-8.841303e-21" iyy="2.381893e-05" iyz="1.766354e-21" izz="5.385323e-05"/>
  </inertial>
  <visual>
     <origin xyz="0.000000 0.000000 -0.019000" rpy="0.00000000 1.57079633 0.00000000"/>
     <geometry>
     <mesh filename="package://robot_assembler/meshes/fr12_h101.dae" scale="1.000000 1.000000 1.000000"/>
     </geometry>
  </visual>
  <collision>
     <origin xyz="0.000000 0.000000 -0.019000" rpy="0.00000000 1.57079633 0.00000000"/>
     <geometry>
     <mesh filename="package://robot_assembler/meshes/fr12_h101.dae" scale="1.000000 1.000000 1.000000"/>
     </geometry>
  </collision>
  <visual>
     <origin xyz="-0.000000 0.063250 -0.019000" rpy="-3.01372919 -1.57079633 3.01372919"/>
     <geometry>
     <mesh filename="package://robot_assembler/meshes/xm430_dynamixel.dae" scale="1.000000 1.000000 1.000000"/>
     </geometry>
  </visual>
  <collision>
     <origin xyz="-0.000000 0.063250 -0.019000" rpy="-3.01372919 -1.57079633 3.01372919"/>
     <geometry>
     <mesh filename="package://robot_assembler/meshes/xm430_dynamixel.dae" scale="1.000000 1.000000 1.000000"/>
     </geometry>
  </collision>
  </link>
  <xacro:gazebo_link_reference link_name="LINK29" />
  <link name="LINK29">
  <inertial>
     <mass value="0.10"/>
     <origin rpy="0 0 0" xyz="-0.05 -0.0485 0.022"/>
     <inertia ixx="3.202708e-05" ixy="-4.569801e-35" ixz="1.241189e-35" iyy="2.478750e-05" iyz="2.894099e-21" izz="2.077708e-05"/>
  </inertial>
  <visual>
     <origin xyz="-0.050000 -0.050000 0.010000" rpy="-1.57079633 0.00000000 -0.00000000"/>
     <geometry>
     <mesh filename="package://robot_assembler/meshes/wheel.dae" scale="0.001000 0.001000 0.001000"/>
     </geometry>
  </visual>
  <collision>
     <origin xyz="-0.050000 -0.050000 0.010000" rpy="-1.57079633 0.00000000 -0.00000000"/>
     <geometry>
     <mesh filename="package://robot_assembler/meshes/wheel.dae" scale="0.001000 0.001000 0.001000"/>
     </geometry>
  </collision>
  </link>
  <xacro:gazebo_transmission joint_name="JOINT0" />
  <joint name="JOINT0" type="revolute">
     <parent link="BASE"/>
     <child link="LINK0"/>
     <origin xyz="0.012000 -0.049000 0.025000" rpy="0.78539816 1.57079633 -0.78539816"/>
     <axis xyz="0 0 1"/>
     <limit effort="200" lower="-3.14159" upper="3.14159" velocity="40"/>
  </joint>
  <xacro:gazebo_transmission joint_name="JOINT1" />
  <joint name="JOINT1" type="revolute">
     <parent link="LINK0"/>
     <child link="LINK1"/>
     <origin xyz="0.010000 0.020500 0.028500" rpy="-1.57079633 -0.52359878 3.14159265"/>
     <axis xyz="0 0 1"/>
     <limit effort="200" lower="-3.14159" upper="3.14159" velocity="40"/>
  </joint>
  <xacro:gazebo_transmission joint_name="JOINT2" />
  <joint name="JOINT2" type="revolute">
     <parent link="LINK1"/>
     <child link="LINK2"/>
     <origin xyz="0.019000 0.000000 0.020600" rpy="-2.30283502 1.57079633 -2.30283502"/>
     <axis xyz="0 0 1"/>
     <limit effort="200" lower="-3.14159" upper="3.14159" velocity="40"/>
  </joint>
  <xacro:gazebo_transmission joint_name="JOINT3" />
  <joint name="JOINT3" type="revolute">
     <parent link="LINK2"/>
     <child link="LINK3"/>
     <origin xyz="0.000000 -0.083000 -0.000000" rpy="0.00000000 0.00000000 -0.00000000"/>
     <axis xyz="0 0 1"/>
     <limit effort="200" lower="-3.14159" upper="3.14159" velocity="40"/>
  </joint>
  <xacro:gazebo_transmission joint_name="JOINT4" />
  <joint name="JOINT4" type="revolute">
     <parent link="LINK3"/>
     <child link="LINK4"/>
     <origin xyz="-0.000000 -0.068500 0.000000" rpy="-0.00000000 0.00000000 -0.00000000"/>
     <axis xyz="0 0 1"/>
     <limit effort="200" lower="-3.14159" upper="3.14159" velocity="40"/>
  </joint>
  <xacro:gazebo_transmission joint_name="JOINT5" />
  <joint name="JOINT5" type="revolute">
     <parent link="LINK4"/>
     <child link="LINK5"/>
     <origin xyz="0.020600 -0.032000 -0.019000" rpy="-1.33931896 1.57079633 1.80227369"/>
     <axis xyz="0 0 1"/>
     <limit effort="200" lower="-3.14159" upper="3.14159" velocity="40"/>
  </joint>
  <xacro:gazebo_transmission joint_name="JOINT6" />
  <joint name="JOINT6" type="revolute">
     <parent link="LINK5"/>
     <child link="LINK6"/>
     <origin xyz="-0.000000 0.069750 0.044500" rpy="1.57079633 0.00000000 -3.14159265"/>
     <axis xyz="0 0 1"/>
     <limit effort="200" lower="-3.14159" upper="3.14159" velocity="40"/>
  </joint>
  <xacro:gazebo_transmission joint_name="JOINT7" />
  <joint name="JOINT7" type="revolute">
     <parent link="LINK6"/>
     <child link="LINK7"/>
     <origin xyz="0.008000 0.019000 0.014250" rpy="2.55359005 1.57079633 -2.15879893"/>
     <axis xyz="0 0 1"/>
     <limit effort="200" lower="-3.14159" upper="3.14159" velocity="40"/>
  </joint>
  <xacro:gazebo_transmission joint_name="JOINT8" />
  <joint name="JOINT8" type="revolute">
     <parent link="BASE"/>
     <child link="LINK8"/>
     <origin xyz="0.012000 0.049000 0.025000" rpy="-0.78539816 -1.57079633 -0.78539816"/>
     <axis xyz="0 0 1"/>
     <limit effort="200" lower="-3.14159" upper="3.14159" velocity="40"/>
  </joint>
  <xacro:gazebo_transmission joint_name="JOINT9" />
  <joint name="JOINT9" type="revolute">
     <parent link="LINK8"/>
     <child link="LINK9"/>
     <origin xyz="-0.010000 0.019000 0.028500" rpy="-1.57079633 0.52359878 -3.14159265"/>
     <axis xyz="0 0 1"/>
     <limit effort="200" lower="-3.14159" upper="3.14159" velocity="40"/>
  </joint>
  <xacro:gazebo_transmission joint_name="JOINT10" />
  <joint name="JOINT10" type="revolute">
     <parent link="LINK9"/>
     <child link="LINK10"/>
     <origin xyz="-0.019000 -0.000000 0.020600" rpy="-0.60136073 -1.57079633 0.60136073"/>
     <axis xyz="0 0 1"/>
     <limit effort="200" lower="-3.14159" upper="3.14159" velocity="40"/>
  </joint>
  <xacro:gazebo_transmission joint_name="JOINT11" />
  <joint name="JOINT11" type="revolute">
     <parent link="LINK10"/>
     <child link="LINK11"/>
     <origin xyz="0.000000 -0.083000 0.000000" rpy="0.00000000 0.00000000 0.00000000"/>
     <axis xyz="0 0 1"/>
     <limit effort="200" lower="-3.14159" upper="3.14159" velocity="40"/>
  </joint>
  <xacro:gazebo_transmission joint_name="JOINT12" />
  <joint name="JOINT12" type="revolute">
     <parent link="LINK11"/>
     <child link="LINK12"/>
     <origin xyz="-0.000000 -0.068500 0.000000" rpy="-0.00000000 0.00000000 -0.00000000"/>
     <axis xyz="0 0 1"/>
     <limit effort="200" lower="-3.14159" upper="3.14159" velocity="40"/>
  </joint>
  <xacro:gazebo_transmission joint_name="JOINT13" />
  <joint name="JOINT13" type="revolute">
     <parent link="LINK12"/>
     <child link="LINK13"/>
     <origin xyz="-0.020600 -0.032000 -0.019000" rpy="2.08560228 -1.57079633 1.05599037"/>
     <axis xyz="0 0 1"/>
     <limit effort="200" lower="-3.14159" upper="3.14159" velocity="40"/>
  </joint>
  <xacro:gazebo_transmission joint_name="JOINT14" />
  <joint name="JOINT14" type="revolute">
     <parent link="LINK13"/>
     <child link="LINK14"/>
     <origin xyz="-0.000000 0.069750 0.044500" rpy="1.57079633 0.00000000 -3.14159265"/>
     <axis xyz="0 0 1"/>
     <limit effort="200" lower="-3.14159" upper="3.14159" velocity="40"/>
  </joint>
  <xacro:gazebo_transmission joint_name="JOINT15" />
  <joint name="JOINT15" type="revolute">
     <parent link="LINK14"/>
     <child link="LINK15"/>
     <origin xyz="-0.008000 0.019000 0.014250" rpy="2.35619449 -1.57079633 2.35619449"/>
     <axis xyz="0 0 1"/>
     <limit effort="200" lower="-3.14159" upper="3.14159" velocity="40"/>
  </joint>
  <xacro:gazebo_transmission joint_name="JOINT16" />
  <joint name="JOINT16" type="revolute">
     <parent link="BASE"/>
     <child link="LINK16"/>
     <origin xyz="0.012000 -0.032000 -0.040000" rpy="3.14159265 0.00000000 1.57079633"/>
     <axis xyz="0 0 1"/>
     <limit effort="200" lower="-3.14159" upper="3.14159" velocity="40"/>
  </joint>
  <xacro:no_gazebo_transmission joint_name="JOINT17" />
  <joint name="JOINT17" type="revolute">
     <parent link="LINK16"/>
     <child link="LINK17"/>
     <origin xyz="-0.000000 -0.020500 0.028000" rpy="-1.57079633 -0.00000000 0.00000000"/>
     <axis xyz="0 0 1"/>
     <limit effort="200" lower="-3.14159" upper="3.14159" velocity="40"/>
  </joint>
  <xacro:gazebo_transmission joint_name="JOINT18" />
  <joint name="JOINT18" type="revolute">
     <parent link="LINK17"/>
     <child link="LINK18"/>
     <origin xyz="0.019000 0.000000 0.020600" rpy="-2.88816299 1.57079633 -2.88816299"/>
     <axis xyz="0 0 1"/>
     <limit effort="200" lower="-3.14159" upper="3.14159" velocity="40"/>
  </joint>
  <xacro:no_gazebo_transmission joint_name="JOINT19" />
  <joint name="JOINT19" type="revolute">
     <parent link="LINK18"/>
     <child link="LINK19"/>
     <origin xyz="-0.072405 -0.065590 -0.019000" rpy="-1.11160138 1.57079633 0.98279372"/>
     <axis xyz="0 0 1"/>
     <limit effort="200" lower="-3.14159" upper="3.14159" velocity="40"/>
  </joint>
  <xacro:gazebo_transmission joint_name="JOINT20" />
  <joint name="JOINT20" type="revolute">
     <parent link="LINK19"/>
     <child link="LINK20"/>
     <origin xyz="0.019000 0.063250 -0.019000" rpy="0.33983691 1.57079633 0.33983691"/>
     <axis xyz="0 0 1"/>
     <limit effort="200" lower="-3.14159" upper="3.14159" velocity="40"/>
  </joint>
  <xacro:no_gazebo_transmission joint_name="JOINT21" />
  <joint name="JOINT21" type="revolute">
     <parent link="LINK17"/>
     <child link="LINK21"/>
     <origin xyz="-0.000000 -0.081000 0.000000" rpy="0.00000000 0.00000000 3.14159265"/>
     <axis xyz="0 0 1"/>
     <limit effort="200" lower="-3.14159" upper="3.14159" velocity="40"/>
  </joint>
  <xacro:gazebo_transmission joint_name="JOINT22" />
  <joint name="JOINT22" type="revolute">
     <parent link="LINK21"/>
     <child link="LINK22"/>
     <origin xyz="0.019000 0.063250 -0.019000" rpy="-0.12786347 1.57079633 -0.12786347"/>
     <axis xyz="0 0 1"/>
     <limit effort="200" lower="-3.14159" upper="3.14159" velocity="40"/>
  </joint>
  <xacro:gazebo_transmission joint_name="JOINT23" />
  <joint name="JOINT23" type="revolute">
     <parent link="BASE"/>
     <child link="LINK23"/>
     <origin xyz="0.012000 0.032000 -0.040000" rpy="3.14159265 0.00000000 1.57079633"/>
     <axis xyz="0 0 1"/>
     <limit effort="200" lower="-3.14159" upper="3.14159" velocity="40"/>
  </joint>
  <xacro:no_gazebo_transmission joint_name="JOINT24" />
  <joint name="JOINT24" type="revolute">
     <parent link="LINK23"/>
     <child link="LINK24"/>
     <origin xyz="-0.000000 -0.020500 0.028000" rpy="-1.57079633 -0.00000000 0.00000000"/>
     <axis xyz="0 0 1"/>
     <limit effort="200" lower="-3.14159" upper="3.14159" velocity="40"/>
  </joint>
  <xacro:gazebo_transmission joint_name="JOINT25" />
  <joint name="JOINT25" type="revolute">
     <parent link="LINK24"/>
     <child link="LINK25"/>
     <origin xyz="-0.019000 0.000000 0.020600" rpy="-1.11791708 -1.57079633 1.11791708"/>
     <axis xyz="0 0 1"/>
     <limit effort="200" lower="-3.14159" upper="3.14159" velocity="40"/>
  </joint>
  <xacro:no_gazebo_transmission joint_name="JOINT26" />
  <joint name="JOINT26" type="revolute">
     <parent link="LINK25"/>
     <child link="LINK26"/>
     <origin xyz="0.072405 -0.065590 -0.019000" rpy="-2.70629754 -1.57079633 0.61190243"/>
     <axis xyz="0 0 1"/>
     <limit effort="200" lower="-3.14159" upper="3.14159" velocity="40"/>
  </joint>
  <xacro:gazebo_transmission joint_name="JOINT27" />
  <joint name="JOINT27" type="revolute">
     <parent link="LINK26"/>
     <child link="LINK27"/>
     <origin xyz="-0.019000 0.063250 -0.019000" rpy="2.49892323 -1.57079633 -2.49892323"/>
     <axis xyz="0 0 1"/>
     <limit effort="200" lower="-3.14159" upper="3.14159" velocity="40"/>
  </joint>
  <xacro:no_gazebo_transmission joint_name="JOINT28" />
  <joint name="JOINT28" type="revolute">
     <parent link="LINK24"/>
     <child link="LINK28"/>
     <origin xyz="0.000000 -0.081000 -0.000000" rpy="-0.00000000 -0.00000000 -3.14159265"/>
     <axis xyz="0 0 1"/>
     <limit effort="200" lower="-3.14159" upper="3.14159" velocity="40"/>
  </joint>
  <xacro:gazebo_transmission joint_name="JOINT29" />
  <joint name="JOINT29" type="revolute">
     <parent link="LINK28"/>
     <child link="LINK29"/>
     <origin xyz="-0.019000 0.063250 -0.019000" rpy="-3.01372919 -1.57079633 3.01372919"/>
     <axis xyz="0 0 1"/>
     <limit effort="200" lower="-3.14159" upper="3.14159" velocity="40"/>
  </joint>

  <!-- Gazebo plugin for ROS Control -->
  <gazebo>
    <plugin name="gazebo_ros_control" filename="libgazebo_ros_control.so">
      <!--robotNamespace>/</robotNamespace-->
      <legacyModeNS>false</legacyModeNS>
      <robotSimType>gazebo_ros_control/DefaultRobotHWSim</robotSimType>
    </plugin>
  </gazebo>
</robot>
